[2024-12-12T15:25:54.000+0000] {taskinstance.py:1103} INFO - Dependencies all met for dep_context=non-requeueable deps ti=<TaskInstance: api_analysis_pipeline.merge_results manual__2024-12-12T15:25:45.717954+00:00 [queued]>
[2024-12-12T15:25:54.005+0000] {taskinstance.py:1103} INFO - Dependencies all met for dep_context=requeueable deps ti=<TaskInstance: api_analysis_pipeline.merge_results manual__2024-12-12T15:25:45.717954+00:00 [queued]>
[2024-12-12T15:25:54.005+0000] {taskinstance.py:1308} INFO - Starting attempt 1 of 3
[2024-12-12T15:25:54.012+0000] {taskinstance.py:1327} INFO - Executing <Task(PythonOperator): merge_results> on 2024-12-12 15:25:45.717954+00:00
[2024-12-12T15:25:54.017+0000] {standard_task_runner.py:57} INFO - Started process 1582 to run task
[2024-12-12T15:25:54.020+0000] {standard_task_runner.py:84} INFO - Running: ['***', 'tasks', 'run', 'api_analysis_pipeline', 'merge_results', 'manual__2024-12-12T15:25:45.717954+00:00', '--job-id', '522', '--raw', '--subdir', 'DAGS_FOLDER/dag_api_callers.py', '--cfg-path', '/tmp/tmpbmfd7kxp']
[2024-12-12T15:25:54.021+0000] {standard_task_runner.py:85} INFO - Job 522: Subtask merge_results
[2024-12-12T15:25:54.050+0000] {task_command.py:410} INFO - Running <TaskInstance: api_analysis_pipeline.merge_results manual__2024-12-12T15:25:45.717954+00:00 [running]> on host 772549cb3cf8
[2024-12-12T15:25:54.094+0000] {taskinstance.py:1545} INFO - Exporting env vars: AIRFLOW_CTX_DAG_OWNER='***' AIRFLOW_CTX_DAG_ID='api_analysis_pipeline' AIRFLOW_CTX_TASK_ID='merge_results' AIRFLOW_CTX_EXECUTION_DATE='2024-12-12T15:25:45.717954+00:00' AIRFLOW_CTX_TRY_NUMBER='1' AIRFLOW_CTX_DAG_RUN_ID='manual__2024-12-12T15:25:45.717954+00:00'
[2024-12-12T15:25:54.098+0000] {taskinstance.py:1824} ERROR - Task failed with exception
Traceback (most recent call last):
  File "/home/airflow/.local/lib/python3.9/site-packages/airflow/operators/python.py", line 181, in execute
    return_value = self.execute_callable()
  File "/home/airflow/.local/lib/python3.9/site-packages/airflow/operators/python.py", line 198, in execute_callable
    return self.python_callable(*self.op_args, **self.op_kwargs)
  File "/opt/airflow/dags/dag_api_callers.py", line 37, in merge_results
    all_data = pd.concat([pd.read_csv(f'/opt/airflow/data/{file}') for file in files])
  File "/opt/airflow/dags/dag_api_callers.py", line 37, in <listcomp>
    all_data = pd.concat([pd.read_csv(f'/opt/airflow/data/{file}') for file in files])
  File "/home/airflow/.local/lib/python3.9/site-packages/pandas/util/_decorators.py", line 211, in wrapper
    return func(*args, **kwargs)
  File "/home/airflow/.local/lib/python3.9/site-packages/pandas/util/_decorators.py", line 331, in wrapper
    return func(*args, **kwargs)
  File "/home/airflow/.local/lib/python3.9/site-packages/pandas/io/parsers/readers.py", line 950, in read_csv
    return _read(filepath_or_buffer, kwds)
  File "/home/airflow/.local/lib/python3.9/site-packages/pandas/io/parsers/readers.py", line 605, in _read
    parser = TextFileReader(filepath_or_buffer, **kwds)
  File "/home/airflow/.local/lib/python3.9/site-packages/pandas/io/parsers/readers.py", line 1442, in __init__
    self._engine = self._make_engine(f, self.engine)
  File "/home/airflow/.local/lib/python3.9/site-packages/pandas/io/parsers/readers.py", line 1753, in _make_engine
    return mapping[engine](f, **self.options)
  File "/home/airflow/.local/lib/python3.9/site-packages/pandas/io/parsers/c_parser_wrapper.py", line 79, in __init__
    self._reader = parsers.TextReader(src, **kwds)
  File "pandas/_libs/parsers.pyx", line 547, in pandas._libs.parsers.TextReader.__cinit__
  File "pandas/_libs/parsers.pyx", line 636, in pandas._libs.parsers.TextReader._get_header
  File "pandas/_libs/parsers.pyx", line 852, in pandas._libs.parsers.TextReader._tokenize_rows
  File "pandas/_libs/parsers.pyx", line 1965, in pandas._libs.parsers.raise_parser_error
UnicodeDecodeError: 'utf-8' codec can't decode byte 0x89 in position 0: invalid start byte
[2024-12-12T15:25:54.105+0000] {taskinstance.py:1345} INFO - Marking task as UP_FOR_RETRY. dag_id=api_analysis_pipeline, task_id=merge_results, execution_date=20241212T152545, start_date=20241212T152554, end_date=20241212T152554
[2024-12-12T15:25:54.111+0000] {standard_task_runner.py:104} ERROR - Failed to execute job 522 for task merge_results ('utf-8' codec can't decode byte 0x89 in position 0: invalid start byte; 1582)
[2024-12-12T15:25:54.118+0000] {local_task_job_runner.py:225} INFO - Task exited with return code 1
[2024-12-12T15:25:54.132+0000] {taskinstance.py:2653} INFO - 0 downstream tasks scheduled from follow-on schedule check
