[2024-12-12T15:00:04.713+0000] {taskinstance.py:1103} INFO - Dependencies all met for dep_context=non-requeueable deps ti=<TaskInstance: weather_pipeline.analyze_weather_data scheduled__2024-12-12T14:00:00+00:00 [queued]>
[2024-12-12T15:00:04.718+0000] {taskinstance.py:1103} INFO - Dependencies all met for dep_context=requeueable deps ti=<TaskInstance: weather_pipeline.analyze_weather_data scheduled__2024-12-12T14:00:00+00:00 [queued]>
[2024-12-12T15:00:04.719+0000] {taskinstance.py:1308} INFO - Starting attempt 1 of 3
[2024-12-12T15:00:04.728+0000] {taskinstance.py:1327} INFO - Executing <Task(PythonOperator): analyze_weather_data> on 2024-12-12 14:00:00+00:00
[2024-12-12T15:00:04.752+0000] {standard_task_runner.py:57} INFO - Started process 1042 to run task
[2024-12-12T15:00:04.757+0000] {standard_task_runner.py:84} INFO - Running: ['***', 'tasks', 'run', 'weather_pipeline', 'analyze_weather_data', 'scheduled__2024-12-12T14:00:00+00:00', '--job-id', '503', '--raw', '--subdir', 'DAGS_FOLDER/dag_weather.py', '--cfg-path', '/tmp/tmpc91p3dsq']
[2024-12-12T15:00:04.759+0000] {standard_task_runner.py:85} INFO - Job 503: Subtask analyze_weather_data
[2024-12-12T15:00:04.806+0000] {task_command.py:410} INFO - Running <TaskInstance: weather_pipeline.analyze_weather_data scheduled__2024-12-12T14:00:00+00:00 [running]> on host a6279f42b2e1
[2024-12-12T15:00:04.900+0000] {taskinstance.py:1545} INFO - Exporting env vars: AIRFLOW_CTX_DAG_OWNER='***' AIRFLOW_CTX_DAG_ID='weather_pipeline' AIRFLOW_CTX_TASK_ID='analyze_weather_data' AIRFLOW_CTX_EXECUTION_DATE='2024-12-12T14:00:00+00:00' AIRFLOW_CTX_TRY_NUMBER='1' AIRFLOW_CTX_DAG_RUN_ID='scheduled__2024-12-12T14:00:00+00:00'
[2024-12-12T15:00:04.927+0000] {taskinstance.py:1824} ERROR - Task failed with exception
Traceback (most recent call last):
  File "/home/airflow/.local/lib/python3.9/site-packages/pandas/core/indexes/base.py", line 3802, in get_loc
    return self._engine.get_loc(casted_key)
  File "pandas/_libs/index.pyx", line 138, in pandas._libs.index.IndexEngine.get_loc
  File "pandas/_libs/index.pyx", line 165, in pandas._libs.index.IndexEngine.get_loc
  File "pandas/_libs/hashtable_class_helper.pxi", line 5745, in pandas._libs.hashtable.PyObjectHashTable.get_item
  File "pandas/_libs/hashtable_class_helper.pxi", line 5753, in pandas._libs.hashtable.PyObjectHashTable.get_item
KeyError: 'current_temperature_2m'

The above exception was the direct cause of the following exception:

Traceback (most recent call last):
  File "/home/airflow/.local/lib/python3.9/site-packages/airflow/operators/python.py", line 181, in execute
    return_value = self.execute_callable()
  File "/home/airflow/.local/lib/python3.9/site-packages/airflow/operators/python.py", line 198, in execute_callable
    return self.python_callable(*self.op_args, **self.op_kwargs)
  File "/opt/airflow/dags/dag_weather.py", line 41, in analyze_weather_data
    stats = df['current_temperature_2m'].describe()
  File "/home/airflow/.local/lib/python3.9/site-packages/pandas/core/frame.py", line 3807, in __getitem__
    indexer = self.columns.get_loc(key)
  File "/home/airflow/.local/lib/python3.9/site-packages/pandas/core/indexes/base.py", line 3804, in get_loc
    raise KeyError(key) from err
KeyError: 'current_temperature_2m'
[2024-12-12T15:00:04.944+0000] {taskinstance.py:1345} INFO - Marking task as UP_FOR_RETRY. dag_id=weather_pipeline, task_id=analyze_weather_data, execution_date=20241212T140000, start_date=20241212T150004, end_date=20241212T150004
[2024-12-12T15:00:04.959+0000] {standard_task_runner.py:104} ERROR - Failed to execute job 503 for task analyze_weather_data ('current_temperature_2m'; 1042)
[2024-12-12T15:00:04.979+0000] {local_task_job_runner.py:225} INFO - Task exited with return code 1
[2024-12-12T15:00:05.004+0000] {taskinstance.py:2653} INFO - 0 downstream tasks scheduled from follow-on schedule check
