[2024-12-12T15:34:51.892+0000] {taskinstance.py:1103} INFO - Dependencies all met for dep_context=non-requeueable deps ti=<TaskInstance: weather_pipeline.plot_temperature manual__2024-12-12T15:34:44.609130+00:00 [queued]>
[2024-12-12T15:34:51.898+0000] {taskinstance.py:1103} INFO - Dependencies all met for dep_context=requeueable deps ti=<TaskInstance: weather_pipeline.plot_temperature manual__2024-12-12T15:34:44.609130+00:00 [queued]>
[2024-12-12T15:34:51.898+0000] {taskinstance.py:1308} INFO - Starting attempt 1 of 3
[2024-12-12T15:34:51.917+0000] {taskinstance.py:1327} INFO - Executing <Task(PythonOperator): plot_temperature> on 2024-12-12 15:34:44.609130+00:00
[2024-12-12T15:34:51.931+0000] {standard_task_runner.py:57} INFO - Started process 2064 to run task
[2024-12-12T15:34:51.936+0000] {standard_task_runner.py:84} INFO - Running: ['***', 'tasks', 'run', 'weather_pipeline', 'plot_temperature', 'manual__2024-12-12T15:34:44.609130+00:00', '--job-id', '526', '--raw', '--subdir', 'DAGS_FOLDER/dag_weather.py', '--cfg-path', '/tmp/tmpf3luq412']
[2024-12-12T15:34:51.939+0000] {standard_task_runner.py:85} INFO - Job 526: Subtask plot_temperature
[2024-12-12T15:34:51.974+0000] {task_command.py:410} INFO - Running <TaskInstance: weather_pipeline.plot_temperature manual__2024-12-12T15:34:44.609130+00:00 [running]> on host 772549cb3cf8
[2024-12-12T15:34:52.035+0000] {taskinstance.py:1545} INFO - Exporting env vars: AIRFLOW_CTX_DAG_OWNER='***' AIRFLOW_CTX_DAG_ID='weather_pipeline' AIRFLOW_CTX_TASK_ID='plot_temperature' AIRFLOW_CTX_EXECUTION_DATE='2024-12-12T15:34:44.609130+00:00' AIRFLOW_CTX_TRY_NUMBER='1' AIRFLOW_CTX_DAG_RUN_ID='manual__2024-12-12T15:34:44.609130+00:00'
[2024-12-12T15:34:52.048+0000] {taskinstance.py:1824} ERROR - Task failed with exception
Traceback (most recent call last):
  File "pandas/_libs/tslib.pyx", line 605, in pandas._libs.tslib.array_to_datetime
  File "pandas/_libs/tslibs/parsing.pyx", line 318, in pandas._libs.tslibs.parsing.parse_datetime_string
  File "/home/airflow/.local/lib/python3.9/site-packages/dateutil/parser/_parser.py", line 1368, in parse
    return DEFAULTPARSER.parse(timestr, **kwargs)
  File "/home/airflow/.local/lib/python3.9/site-packages/dateutil/parser/_parser.py", line 643, in parse
    raise ParserError("Unknown string format: %s", timestr)
dateutil.parser._parser.ParserError: Unknown string format: current_time

During handling of the above exception, another exception occurred:

Traceback (most recent call last):
  File "pandas/_libs/tslib.pyx", line 616, in pandas._libs.tslib.array_to_datetime
TypeError: invalid string coercion to datetime for "current_time" at position 1

During handling of the above exception, another exception occurred:

Traceback (most recent call last):
  File "/home/airflow/.local/lib/python3.9/site-packages/airflow/operators/python.py", line 181, in execute
    return_value = self.execute_callable()
  File "/home/airflow/.local/lib/python3.9/site-packages/airflow/operators/python.py", line 198, in execute_callable
    return self.python_callable(*self.op_args, **self.op_kwargs)
  File "/opt/airflow/dags/dag_weather.py", line 50, in plot_temperature
    df['time'] = pd.to_datetime(df['current_time'])
  File "/home/airflow/.local/lib/python3.9/site-packages/pandas/core/tools/datetimes.py", line 1068, in to_datetime
    values = convert_listlike(arg._values, format)
  File "/home/airflow/.local/lib/python3.9/site-packages/pandas/core/tools/datetimes.py", line 438, in _convert_listlike_datetimes
    result, tz_parsed = objects_to_datetime64ns(
  File "/home/airflow/.local/lib/python3.9/site-packages/pandas/core/arrays/datetimes.py", line 2177, in objects_to_datetime64ns
    result, tz_parsed = tslib.array_to_datetime(
  File "pandas/_libs/tslib.pyx", line 427, in pandas._libs.tslib.array_to_datetime
  File "pandas/_libs/tslib.pyx", line 683, in pandas._libs.tslib.array_to_datetime
  File "pandas/_libs/tslib.pyx", line 829, in pandas._libs.tslib._array_to_datetime_object
  File "pandas/_libs/tslib.pyx", line 819, in pandas._libs.tslib._array_to_datetime_object
  File "pandas/_libs/tslibs/parsing.pyx", line 318, in pandas._libs.tslibs.parsing.parse_datetime_string
  File "/home/airflow/.local/lib/python3.9/site-packages/dateutil/parser/_parser.py", line 1368, in parse
    return DEFAULTPARSER.parse(timestr, **kwargs)
  File "/home/airflow/.local/lib/python3.9/site-packages/dateutil/parser/_parser.py", line 643, in parse
    raise ParserError("Unknown string format: %s", timestr)
dateutil.parser._parser.ParserError: Unknown string format: current_time present at position 1
[2024-12-12T15:34:52.059+0000] {taskinstance.py:1345} INFO - Marking task as UP_FOR_RETRY. dag_id=weather_pipeline, task_id=plot_temperature, execution_date=20241212T153444, start_date=20241212T153451, end_date=20241212T153452
[2024-12-12T15:34:52.065+0000] {standard_task_runner.py:104} ERROR - Failed to execute job 526 for task plot_temperature (Unknown string format: current_time present at position 1; 2064)
[2024-12-12T15:34:52.078+0000] {local_task_job_runner.py:225} INFO - Task exited with return code 1
[2024-12-12T15:34:52.090+0000] {taskinstance.py:2653} INFO - 0 downstream tasks scheduled from follow-on schedule check
