[2024-12-12T15:44:57.543+0000] {taskinstance.py:1103} INFO - Dependencies all met for dep_context=non-requeueable deps ti=<TaskInstance: weather_pipeline.plot_temperature manual__2024-12-12T15:34:44.609130+00:00 [queued]>
[2024-12-12T15:44:57.549+0000] {taskinstance.py:1103} INFO - Dependencies all met for dep_context=requeueable deps ti=<TaskInstance: weather_pipeline.plot_temperature manual__2024-12-12T15:34:44.609130+00:00 [queued]>
[2024-12-12T15:44:57.549+0000] {taskinstance.py:1308} INFO - Starting attempt 3 of 3
[2024-12-12T15:44:57.559+0000] {taskinstance.py:1327} INFO - Executing <Task(PythonOperator): plot_temperature> on 2024-12-12 15:34:44.609130+00:00
[2024-12-12T15:44:57.576+0000] {standard_task_runner.py:57} INFO - Started process 484 to run task
[2024-12-12T15:44:57.585+0000] {standard_task_runner.py:84} INFO - Running: ['***', 'tasks', 'run', 'weather_pipeline', 'plot_temperature', 'manual__2024-12-12T15:34:44.609130+00:00', '--job-id', '530', '--raw', '--subdir', 'DAGS_FOLDER/dag_weather.py', '--cfg-path', '/tmp/tmppczopjeg']
[2024-12-12T15:44:57.618+0000] {standard_task_runner.py:85} INFO - Job 530: Subtask plot_temperature
[2024-12-12T15:44:57.777+0000] {task_command.py:410} INFO - Running <TaskInstance: weather_pipeline.plot_temperature manual__2024-12-12T15:34:44.609130+00:00 [running]> on host c89d57c81a72
[2024-12-12T15:44:57.961+0000] {taskinstance.py:1545} INFO - Exporting env vars: AIRFLOW_CTX_DAG_OWNER='***' AIRFLOW_CTX_DAG_ID='weather_pipeline' AIRFLOW_CTX_TASK_ID='plot_temperature' AIRFLOW_CTX_EXECUTION_DATE='2024-12-12T15:34:44.609130+00:00' AIRFLOW_CTX_TRY_NUMBER='3' AIRFLOW_CTX_DAG_RUN_ID='manual__2024-12-12T15:34:44.609130+00:00'
[2024-12-12T15:44:57.998+0000] {taskinstance.py:1824} ERROR - Task failed with exception
Traceback (most recent call last):
  File "/home/airflow/.local/lib/python3.9/site-packages/airflow/operators/python.py", line 181, in execute
    return_value = self.execute_callable()
  File "/home/airflow/.local/lib/python3.9/site-packages/airflow/operators/python.py", line 198, in execute_callable
    return self.python_callable(*self.op_args, **self.op_kwargs)
  File "/opt/airflow/dags/dag_weather.py", line 49, in plot_temperature
    df = pd.read_csv('/opt/airflow/data/weather.csv')
  File "/home/airflow/.local/lib/python3.9/site-packages/pandas/util/_decorators.py", line 211, in wrapper
    return func(*args, **kwargs)
  File "/home/airflow/.local/lib/python3.9/site-packages/pandas/util/_decorators.py", line 331, in wrapper
    return func(*args, **kwargs)
  File "/home/airflow/.local/lib/python3.9/site-packages/pandas/io/parsers/readers.py", line 950, in read_csv
    return _read(filepath_or_buffer, kwds)
  File "/home/airflow/.local/lib/python3.9/site-packages/pandas/io/parsers/readers.py", line 605, in _read
    parser = TextFileReader(filepath_or_buffer, **kwds)
  File "/home/airflow/.local/lib/python3.9/site-packages/pandas/io/parsers/readers.py", line 1442, in __init__
    self._engine = self._make_engine(f, self.engine)
  File "/home/airflow/.local/lib/python3.9/site-packages/pandas/io/parsers/readers.py", line 1735, in _make_engine
    self.handles = get_handle(
  File "/home/airflow/.local/lib/python3.9/site-packages/pandas/io/common.py", line 856, in get_handle
    handle = open(
FileNotFoundError: [Errno 2] No such file or directory: '/opt/airflow/data/weather.csv'
[2024-12-12T15:44:58.022+0000] {taskinstance.py:1345} INFO - Marking task as FAILED. dag_id=weather_pipeline, task_id=plot_temperature, execution_date=20241212T153444, start_date=20241212T154457, end_date=20241212T154458
[2024-12-12T15:44:58.038+0000] {standard_task_runner.py:104} ERROR - Failed to execute job 530 for task plot_temperature ([Errno 2] No such file or directory: '/opt/airflow/data/weather.csv'; 484)
[2024-12-12T15:44:58.066+0000] {local_task_job_runner.py:225} INFO - Task exited with return code 1
[2024-12-12T15:44:58.081+0000] {taskinstance.py:2653} INFO - 0 downstream tasks scheduled from follow-on schedule check
