[2024-12-12T16:09:19.137+0000] {taskinstance.py:1103} INFO - Dependencies all met for dep_context=non-requeueable deps ti=<TaskInstance: weather_pipeline.download_weather_data scheduled__2024-12-12T15:00:00+00:00 [queued]>
[2024-12-12T16:09:19.148+0000] {taskinstance.py:1103} INFO - Dependencies all met for dep_context=requeueable deps ti=<TaskInstance: weather_pipeline.download_weather_data scheduled__2024-12-12T15:00:00+00:00 [queued]>
[2024-12-12T16:09:19.148+0000] {taskinstance.py:1308} INFO - Starting attempt 2 of 3
[2024-12-12T16:09:19.155+0000] {taskinstance.py:1327} INFO - Executing <Task(PythonOperator): download_weather_data> on 2024-12-12 15:00:00+00:00
[2024-12-12T16:09:19.160+0000] {standard_task_runner.py:57} INFO - Started process 189 to run task
[2024-12-12T16:09:19.163+0000] {standard_task_runner.py:84} INFO - Running: ['***', 'tasks', 'run', 'weather_pipeline', 'download_weather_data', 'scheduled__2024-12-12T15:00:00+00:00', '--job-id', '533', '--raw', '--subdir', 'DAGS_FOLDER/dag_weather.py', '--cfg-path', '/tmp/tmpxzej6dw6']
[2024-12-12T16:09:19.165+0000] {standard_task_runner.py:85} INFO - Job 533: Subtask download_weather_data
[2024-12-12T16:09:19.198+0000] {task_command.py:410} INFO - Running <TaskInstance: weather_pipeline.download_weather_data scheduled__2024-12-12T15:00:00+00:00 [running]> on host ad47a164407b
[2024-12-12T16:09:19.274+0000] {taskinstance.py:1545} INFO - Exporting env vars: AIRFLOW_CTX_DAG_OWNER='***' AIRFLOW_CTX_DAG_ID='weather_pipeline' AIRFLOW_CTX_TASK_ID='download_weather_data' AIRFLOW_CTX_EXECUTION_DATE='2024-12-12T15:00:00+00:00' AIRFLOW_CTX_TRY_NUMBER='2' AIRFLOW_CTX_DAG_RUN_ID='scheduled__2024-12-12T15:00:00+00:00'
[2024-12-12T16:09:19.837+0000] {taskinstance.py:1824} ERROR - Task failed with exception
Traceback (most recent call last):
  File "/home/airflow/.local/lib/python3.9/site-packages/airflow/operators/python.py", line 181, in execute
    return_value = self.execute_callable()
  File "/home/airflow/.local/lib/python3.9/site-packages/airflow/operators/python.py", line 198, in execute_callable
    return self.python_callable(*self.op_args, **self.op_kwargs)
  File "/opt/airflow/dags/dag_weather.py", line 24, in download_weather_data
    flattened_data.to_csv(csv_file_path, index=False, mode='a', header=not os.path.exists(csv_file_path))
NameError: name 'os' is not defined
[2024-12-12T16:09:19.845+0000] {taskinstance.py:1345} INFO - Marking task as UP_FOR_RETRY. dag_id=weather_pipeline, task_id=download_weather_data, execution_date=20241212T150000, start_date=20241212T160919, end_date=20241212T160919
[2024-12-12T16:09:19.852+0000] {standard_task_runner.py:104} ERROR - Failed to execute job 533 for task download_weather_data (name 'os' is not defined; 189)
[2024-12-12T16:09:19.885+0000] {local_task_job_runner.py:225} INFO - Task exited with return code 1
[2024-12-12T16:09:19.908+0000] {taskinstance.py:2653} INFO - 0 downstream tasks scheduled from follow-on schedule check
